[2021-07-02 14:57:28,459] {taskinstance.py:876} INFO - Dependencies all met for <TaskInstance: Fusemachines_Airflow_project.prevalent_projects 2021-07-01T00:13:00+00:00 [queued]>
[2021-07-02 14:57:28,470] {taskinstance.py:876} INFO - Dependencies all met for <TaskInstance: Fusemachines_Airflow_project.prevalent_projects 2021-07-01T00:13:00+00:00 [queued]>
[2021-07-02 14:57:28,470] {taskinstance.py:1067} INFO - 
--------------------------------------------------------------------------------
[2021-07-02 14:57:28,470] {taskinstance.py:1068} INFO - Starting attempt 1 of 4
[2021-07-02 14:57:28,470] {taskinstance.py:1069} INFO - 
--------------------------------------------------------------------------------
[2021-07-02 14:57:29,355] {taskinstance.py:1087} INFO - Executing <Task(PythonOperator): prevalent_projects> on 2021-07-01T00:13:00+00:00
[2021-07-02 14:57:29,362] {standard_task_runner.py:52} INFO - Started process 83512 to run task
[2021-07-02 14:57:29,373] {standard_task_runner.py:76} INFO - Running: ['airflow', 'tasks', 'run', 'Fusemachines_Airflow_project', 'prevalent_projects', '2021-07-01T00:13:00+00:00', '--job-id', '172', '--pool', 'default_pool', '--raw', '--subdir', 'DAGS_FOLDER/dag.py', '--cfg-path', '/tmp/tmp6dh4inj2', '--error-file', '/tmp/tmpdmwxci0_']
[2021-07-02 14:57:29,375] {standard_task_runner.py:77} INFO - Job 172: Subtask prevalent_projects
[2021-07-02 14:57:30,262] {logging_mixin.py:104} INFO - Running <TaskInstance: Fusemachines_Airflow_project.prevalent_projects 2021-07-01T00:13:00+00:00 [running]> on host deepika-Inspiron-5570
[2021-07-02 14:57:31,356] {taskinstance.py:1280} INFO - Exporting the following env vars:
AIRFLOW_CTX_DAG_EMAIL=sthadpka93@gmail.com
AIRFLOW_CTX_DAG_OWNER=postgres
AIRFLOW_CTX_DAG_ID=Fusemachines_Airflow_project
AIRFLOW_CTX_TASK_ID=prevalent_projects
AIRFLOW_CTX_EXECUTION_DATE=2021-07-01T00:13:00+00:00
AIRFLOW_CTX_DAG_RUN_ID=scheduled__2021-07-01T00:13:00+00:00
[2021-07-02 14:57:34,786] {local_task_job.py:196} WARNING - State of this instance has been externally set to None. Terminating instance.
[2021-07-02 14:57:34,804] {process_utils.py:100} INFO - Sending Signals.SIGTERM to GPID 83512
[2021-07-02 14:57:34,804] {taskinstance.py:1264} ERROR - Received SIGTERM. Terminating subprocesses.
[2021-07-02 14:57:34,804] {java_gateway.py:1210} INFO - Error while receiving.
Traceback (most recent call last):
  File "/home/deepika/.local/lib/python3.8/site-packages/py4j/java_gateway.py", line 1200, in send_command
    answer = smart_decode(self.stream.readline()[:-1])
  File "/usr/lib/python3.8/socket.py", line 669, in readinto
    return self._sock.recv_into(b)
  File "/home/deepika/.local/lib/python3.8/site-packages/airflow/models/taskinstance.py", line 1266, in signal_handler
    raise AirflowException("Task received SIGTERM signal")
airflow.exceptions.AirflowException: Task received SIGTERM signal
[2021-07-02 14:57:34,809] {java_gateway.py:1050} ERROR - Exception while sending command.
Traceback (most recent call last):
  File "/home/deepika/.local/lib/python3.8/site-packages/py4j/java_gateway.py", line 1200, in send_command
    answer = smart_decode(self.stream.readline()[:-1])
  File "/usr/lib/python3.8/socket.py", line 669, in readinto
    return self._sock.recv_into(b)
  File "/home/deepika/.local/lib/python3.8/site-packages/airflow/models/taskinstance.py", line 1266, in signal_handler
    raise AirflowException("Task received SIGTERM signal")
airflow.exceptions.AirflowException: Task received SIGTERM signal

During handling of the above exception, another exception occurred:

Traceback (most recent call last):
  File "/home/deepika/.local/lib/python3.8/site-packages/py4j/java_gateway.py", line 1033, in send_command
    response = connection.send_command(command)
  File "/home/deepika/.local/lib/python3.8/site-packages/py4j/java_gateway.py", line 1211, in send_command
    raise Py4JNetworkError(
py4j.protocol.Py4JNetworkError: Error while receiving
[2021-07-02 14:57:34,809] {taskinstance.py:1481} ERROR - Task failed with exception
Traceback (most recent call last):
  File "/home/deepika/.local/lib/python3.8/site-packages/airflow/models/taskinstance.py", line 1137, in _run_raw_task
    self._prepare_and_execute_task_with_callbacks(context, task)
  File "/home/deepika/.local/lib/python3.8/site-packages/airflow/models/taskinstance.py", line 1311, in _prepare_and_execute_task_with_callbacks
    result = self._execute_task(context, task_copy)
  File "/home/deepika/.local/lib/python3.8/site-packages/airflow/models/taskinstance.py", line 1341, in _execute_task
    result = task_copy.execute(context=context)
  File "/home/deepika/.local/lib/python3.8/site-packages/airflow/operators/python.py", line 150, in execute
    return_value = self.execute_callable()
  File "/home/deepika/.local/lib/python3.8/site-packages/airflow/operators/python.py", line 161, in execute_callable
    return self.python_callable(*self.op_args, **self.op_kwargs)
  File "/home/deepika/airflow/dags/dag.py", line 48, in prevalent_projects
    load_to_db(task7())
  File "/home/deepika/airflow/dags/main.py", line 22, in load_to_db
    df.write.jdbc(url=url,
  File "/opt/spark/python/pyspark/sql/readwriter.py", line 1445, in jdbc
    self.mode(mode)._jwrite.jdbc(url, table, jprop)
  File "/home/deepika/.local/lib/python3.8/site-packages/py4j/java_gateway.py", line 1304, in __call__
    return_value = get_return_value(
  File "/opt/spark/python/pyspark/sql/utils.py", line 111, in deco
    return f(*a, **kw)
  File "/home/deepika/.local/lib/python3.8/site-packages/py4j/protocol.py", line 334, in get_return_value
    raise Py4JError(
py4j.protocol.Py4JError: An error occurred while calling o88.jdbc
[2021-07-02 14:57:34,812] {taskinstance.py:1524} INFO - Marking task as UP_FOR_RETRY. dag_id=Fusemachines_Airflow_project, task_id=prevalent_projects, execution_date=20210701T001300, start_date=20210702T091228, end_date=20210702T091234
[2021-07-02 14:57:35,014] {process_utils.py:66} INFO - Process psutil.Process(pid=83512, status='terminated', exitcode=1, started='14:57:28') (83512) terminated with exit code 1
