[2021-07-02 13:53:55,141] {taskinstance.py:876} INFO - Dependencies all met for <TaskInstance: Fusemachines_Airflow_project.reached_goals 2021-07-01T00:00:00+00:00 [queued]>
[2021-07-02 13:53:55,149] {taskinstance.py:876} INFO - Dependencies all met for <TaskInstance: Fusemachines_Airflow_project.reached_goals 2021-07-01T00:00:00+00:00 [queued]>
[2021-07-02 13:53:55,150] {taskinstance.py:1067} INFO - 
--------------------------------------------------------------------------------
[2021-07-02 13:53:55,150] {taskinstance.py:1068} INFO - Starting attempt 2 of 4
[2021-07-02 13:53:55,150] {taskinstance.py:1069} INFO - 
--------------------------------------------------------------------------------
[2021-07-02 13:53:55,222] {taskinstance.py:1087} INFO - Executing <Task(PythonOperator): reached_goals> on 2021-07-01T00:00:00+00:00
[2021-07-02 13:53:55,227] {standard_task_runner.py:52} INFO - Started process 34548 to run task
[2021-07-02 13:53:55,238] {standard_task_runner.py:76} INFO - Running: ['airflow', 'tasks', 'run', 'Fusemachines_Airflow_project', 'reached_goals', '2021-07-01T00:00:00+00:00', '--job-id', '46', '--pool', 'default_pool', '--raw', '--subdir', 'DAGS_FOLDER/dag.py', '--cfg-path', '/tmp/tmp008vky_b', '--error-file', '/tmp/tmppmq4cdcf']
[2021-07-02 13:53:55,240] {standard_task_runner.py:77} INFO - Job 46: Subtask reached_goals
[2021-07-02 13:53:55,364] {logging_mixin.py:104} INFO - Running <TaskInstance: Fusemachines_Airflow_project.reached_goals 2021-07-01T00:00:00+00:00 [running]> on host deepika-Inspiron-5570
[2021-07-02 13:53:55,575] {taskinstance.py:1280} INFO - Exporting the following env vars:
AIRFLOW_CTX_DAG_EMAIL=sthadpka93@gmail.com
AIRFLOW_CTX_DAG_OWNER=postgres
AIRFLOW_CTX_DAG_ID=Fusemachines_Airflow_project
AIRFLOW_CTX_TASK_ID=reached_goals
AIRFLOW_CTX_EXECUTION_DATE=2021-07-01T00:00:00+00:00
AIRFLOW_CTX_DAG_RUN_ID=scheduled__2021-07-01T00:00:00+00:00
[2021-07-02 13:53:58,390] {taskinstance.py:1481} ERROR - Task failed with exception
Traceback (most recent call last):
  File "/home/deepika/.local/lib/python3.8/site-packages/airflow/models/taskinstance.py", line 1137, in _run_raw_task
    self._prepare_and_execute_task_with_callbacks(context, task)
  File "/home/deepika/.local/lib/python3.8/site-packages/airflow/models/taskinstance.py", line 1311, in _prepare_and_execute_task_with_callbacks
    result = self._execute_task(context, task_copy)
  File "/home/deepika/.local/lib/python3.8/site-packages/airflow/models/taskinstance.py", line 1341, in _execute_task
    result = task_copy.execute(context=context)
  File "/home/deepika/.local/lib/python3.8/site-packages/airflow/operators/python.py", line 150, in execute
    return_value = self.execute_callable()
  File "/home/deepika/.local/lib/python3.8/site-packages/airflow/operators/python.py", line 161, in execute_callable
    return self.python_callable(*self.op_args, **self.op_kwargs)
  File "/home/deepika/airflow/dags/dag.py", line 35, in reached_goals
    load_to_db(task4())
  File "/home/deepika/airflow/dags/main.py", line 22, in load_to_db
    df.write.jdbc(url=url,
AttributeError: 'int' object has no attribute 'write'
[2021-07-02 13:53:58,392] {taskinstance.py:1524} INFO - Marking task as UP_FOR_RETRY. dag_id=Fusemachines_Airflow_project, task_id=reached_goals, execution_date=20210701T000000, start_date=20210702T080855, end_date=20210702T080858
[2021-07-02 13:53:58,622] {local_task_job.py:151} INFO - Task exited with return code 1
