[2021-07-02 14:54:04,912] {taskinstance.py:876} INFO - Dependencies all met for <TaskInstance: Fusemachines_Airflow_project.most_projects_category 2021-07-01T00:08:00+00:00 [queued]>
[2021-07-02 14:54:04,926] {taskinstance.py:876} INFO - Dependencies all met for <TaskInstance: Fusemachines_Airflow_project.most_projects_category 2021-07-01T00:08:00+00:00 [queued]>
[2021-07-02 14:54:04,926] {taskinstance.py:1067} INFO - 
--------------------------------------------------------------------------------
[2021-07-02 14:54:04,926] {taskinstance.py:1068} INFO - Starting attempt 2 of 4
[2021-07-02 14:54:04,926] {taskinstance.py:1069} INFO - 
--------------------------------------------------------------------------------
[2021-07-02 14:54:06,531] {taskinstance.py:1087} INFO - Executing <Task(PythonOperator): most_projects_category> on 2021-07-01T00:08:00+00:00
[2021-07-02 14:54:06,534] {standard_task_runner.py:52} INFO - Started process 78688 to run task
[2021-07-02 14:54:06,541] {standard_task_runner.py:76} INFO - Running: ['airflow', 'tasks', 'run', 'Fusemachines_Airflow_project', 'most_projects_category', '2021-07-01T00:08:00+00:00', '--job-id', '158', '--pool', 'default_pool', '--raw', '--subdir', 'DAGS_FOLDER/dag.py', '--cfg-path', '/tmp/tmpdijzu1g4', '--error-file', '/tmp/tmpurgwwjnq']
[2021-07-02 14:54:06,542] {standard_task_runner.py:77} INFO - Job 158: Subtask most_projects_category
[2021-07-02 14:54:07,231] {logging_mixin.py:104} INFO - Running <TaskInstance: Fusemachines_Airflow_project.most_projects_category 2021-07-01T00:08:00+00:00 [running]> on host deepika-Inspiron-5570
[2021-07-02 14:54:07,957] {taskinstance.py:1280} INFO - Exporting the following env vars:
AIRFLOW_CTX_DAG_EMAIL=sthadpka93@gmail.com
AIRFLOW_CTX_DAG_OWNER=postgres
AIRFLOW_CTX_DAG_ID=Fusemachines_Airflow_project
AIRFLOW_CTX_TASK_ID=most_projects_category
AIRFLOW_CTX_EXECUTION_DATE=2021-07-01T00:08:00+00:00
AIRFLOW_CTX_DAG_RUN_ID=scheduled__2021-07-01T00:08:00+00:00
[2021-07-02 14:54:20,744] {taskinstance.py:1481} ERROR - Task failed with exception
Traceback (most recent call last):
  File "/home/deepika/.local/lib/python3.8/site-packages/airflow/models/taskinstance.py", line 1137, in _run_raw_task
    self._prepare_and_execute_task_with_callbacks(context, task)
  File "/home/deepika/.local/lib/python3.8/site-packages/airflow/models/taskinstance.py", line 1311, in _prepare_and_execute_task_with_callbacks
    result = self._execute_task(context, task_copy)
  File "/home/deepika/.local/lib/python3.8/site-packages/airflow/models/taskinstance.py", line 1341, in _execute_task
    result = task_copy.execute(context=context)
  File "/home/deepika/.local/lib/python3.8/site-packages/airflow/operators/python.py", line 150, in execute
    return_value = self.execute_callable()
  File "/home/deepika/.local/lib/python3.8/site-packages/airflow/operators/python.py", line 161, in execute_callable
    return self.python_callable(*self.op_args, **self.op_kwargs)
  File "/home/deepika/airflow/dags/dag.py", line 39, in most_projects_category
    load_to_db(task5())
  File "/home/deepika/airflow/dags/main.py", line 22, in load_to_db
    df.write.jdbc(url=url,
  File "/opt/spark/python/pyspark/sql/readwriter.py", line 1445, in jdbc
    self.mode(mode)._jwrite.jdbc(url, table, jprop)
  File "/home/deepika/.local/lib/python3.8/site-packages/py4j/java_gateway.py", line 1304, in __call__
    return_value = get_return_value(
  File "/opt/spark/python/pyspark/sql/utils.py", line 111, in deco
    return f(*a, **kw)
  File "/home/deepika/.local/lib/python3.8/site-packages/py4j/protocol.py", line 326, in get_return_value
    raise Py4JJavaError(
py4j.protocol.Py4JJavaError: An error occurred while calling o79.jdbc.
: org.apache.spark.SparkException: Job aborted due to stage failure: Task 142 in stage 12.0 failed 1 times, most recent failure: Lost task 142.0 in stage 12.0 (TID 764) (192.168.1.106 executor driver): java.sql.BatchUpdateException: Batch entry 0 INSERT INTO Project ("category","count") VALUES ('Workshops',164) was aborted: ERROR: relation "project" does not exist
  Position: 13  Call getNextException to see other errors in the batch.
	at org.postgresql.jdbc.BatchResultHandler.handleError(BatchResultHandler.java:169)
	at org.postgresql.core.ResultHandlerDelegate.handleError(ResultHandlerDelegate.java:52)
	at org.postgresql.core.v3.QueryExecutorImpl.processResults(QueryExecutorImpl.java:2285)
	at org.postgresql.core.v3.QueryExecutorImpl.execute(QueryExecutorImpl.java:520)
	at org.postgresql.jdbc.PgStatement.internalExecuteBatch(PgStatement.java:878)
	at org.postgresql.jdbc.PgStatement.executeBatch(PgStatement.java:901)
	at org.postgresql.jdbc.PgPreparedStatement.executeBatch(PgPreparedStatement.java:1644)
	at org.apache.spark.sql.execution.datasources.jdbc.JdbcUtils$.savePartition(JdbcUtils.scala:692)
	at org.apache.spark.sql.execution.datasources.jdbc.JdbcUtils$.$anonfun$saveTable$1(JdbcUtils.scala:856)
	at org.apache.spark.sql.execution.datasources.jdbc.JdbcUtils$.$anonfun$saveTable$1$adapted(JdbcUtils.scala:854)
	at org.apache.spark.rdd.RDD.$anonfun$foreachPartition$2(RDD.scala:1020)
	at org.apache.spark.rdd.RDD.$anonfun$foreachPartition$2$adapted(RDD.scala:1020)
	at org.apache.spark.SparkContext.$anonfun$runJob$5(SparkContext.scala:2236)
	at org.apache.spark.scheduler.ResultTask.runTask(ResultTask.scala:90)
	at org.apache.spark.scheduler.Task.run(Task.scala:131)
	at org.apache.spark.executor.Executor$TaskRunner.$anonfun$run$3(Executor.scala:497)
	at org.apache.spark.util.Utils$.tryWithSafeFinally(Utils.scala:1439)
	at org.apache.spark.executor.Executor$TaskRunner.run(Executor.scala:500)
	at java.util.concurrent.ThreadPoolExecutor.runWorker(ThreadPoolExecutor.java:1149)
	at java.util.concurrent.ThreadPoolExecutor$Worker.run(ThreadPoolExecutor.java:624)
	at java.lang.Thread.run(Thread.java:748)
Caused by: org.postgresql.util.PSQLException: ERROR: relation "project" does not exist
  Position: 13
	at org.postgresql.core.v3.QueryExecutorImpl.receiveErrorResponse(QueryExecutorImpl.java:2552)
	at org.postgresql.core.v3.QueryExecutorImpl.processResults(QueryExecutorImpl.java:2284)
	... 18 more

Driver stacktrace:
	at org.apache.spark.scheduler.DAGScheduler.failJobAndIndependentStages(DAGScheduler.scala:2258)
	at org.apache.spark.scheduler.DAGScheduler.$anonfun$abortStage$2(DAGScheduler.scala:2207)
	at org.apache.spark.scheduler.DAGScheduler.$anonfun$abortStage$2$adapted(DAGScheduler.scala:2206)
	at scala.collection.mutable.ResizableArray.foreach(ResizableArray.scala:62)
	at scala.collection.mutable.ResizableArray.foreach$(ResizableArray.scala:55)
	at scala.collection.mutable.ArrayBuffer.foreach(ArrayBuffer.scala:49)
	at org.apache.spark.scheduler.DAGScheduler.abortStage(DAGScheduler.scala:2206)
	at org.apache.spark.scheduler.DAGScheduler.$anonfun$handleTaskSetFailed$1(DAGScheduler.scala:1079)
	at org.apache.spark.scheduler.DAGScheduler.$anonfun$handleTaskSetFailed$1$adapted(DAGScheduler.scala:1079)
	at scala.Option.foreach(Option.scala:407)
	at org.apache.spark.scheduler.DAGScheduler.handleTaskSetFailed(DAGScheduler.scala:1079)
	at org.apache.spark.scheduler.DAGSchedulerEventProcessLoop.doOnReceive(DAGScheduler.scala:2445)
	at org.apache.spark.scheduler.DAGSchedulerEventProcessLoop.onReceive(DAGScheduler.scala:2387)
	at org.apache.spark.scheduler.DAGSchedulerEventProcessLoop.onReceive(DAGScheduler.scala:2376)
	at org.apache.spark.util.EventLoop$$anon$1.run(EventLoop.scala:49)
	at org.apache.spark.scheduler.DAGScheduler.runJob(DAGScheduler.scala:868)
	at org.apache.spark.SparkContext.runJob(SparkContext.scala:2196)
	at org.apache.spark.SparkContext.runJob(SparkContext.scala:2217)
	at org.apache.spark.SparkContext.runJob(SparkContext.scala:2236)
	at org.apache.spark.SparkContext.runJob(SparkContext.scala:2261)
	at org.apache.spark.rdd.RDD.$anonfun$foreachPartition$1(RDD.scala:1020)
	at org.apache.spark.rdd.RDDOperationScope$.withScope(RDDOperationScope.scala:151)
	at org.apache.spark.rdd.RDDOperationScope$.withScope(RDDOperationScope.scala:112)
	at org.apache.spark.rdd.RDD.withScope(RDD.scala:414)
	at org.apache.spark.rdd.RDD.foreachPartition(RDD.scala:1018)
	at org.apache.spark.sql.execution.datasources.jdbc.JdbcUtils$.saveTable(JdbcUtils.scala:854)
	at org.apache.spark.sql.execution.datasources.jdbc.JdbcRelationProvider.createRelation(JdbcRelationProvider.scala:63)
	at org.apache.spark.sql.execution.datasources.SaveIntoDataSourceCommand.run(SaveIntoDataSourceCommand.scala:46)
	at org.apache.spark.sql.execution.command.ExecutedCommandExec.sideEffectResult$lzycompute(commands.scala:70)
	at org.apache.spark.sql.execution.command.ExecutedCommandExec.sideEffectResult(commands.scala:68)
	at org.apache.spark.sql.execution.command.ExecutedCommandExec.doExecute(commands.scala:90)
	at org.apache.spark.sql.execution.SparkPlan.$anonfun$execute$1(SparkPlan.scala:180)
	at org.apache.spark.sql.execution.SparkPlan.$anonfun$executeQuery$1(SparkPlan.scala:218)
	at org.apache.spark.rdd.RDDOperationScope$.withScope(RDDOperationScope.scala:151)
	at org.apache.spark.sql.execution.SparkPlan.executeQuery(SparkPlan.scala:215)
	at org.apache.spark.sql.execution.SparkPlan.execute(SparkPlan.scala:176)
	at org.apache.spark.sql.execution.QueryExecution.toRdd$lzycompute(QueryExecution.scala:132)
	at org.apache.spark.sql.execution.QueryExecution.toRdd(QueryExecution.scala:131)
	at org.apache.spark.sql.DataFrameWriter.$anonfun$runCommand$1(DataFrameWriter.scala:989)
	at org.apache.spark.sql.execution.SQLExecution$.$anonfun$withNewExecutionId$5(SQLExecution.scala:103)
	at org.apache.spark.sql.execution.SQLExecution$.withSQLConfPropagated(SQLExecution.scala:163)
	at org.apache.spark.sql.execution.SQLExecution$.$anonfun$withNewExecutionId$1(SQLExecution.scala:90)
	at org.apache.spark.sql.SparkSession.withActive(SparkSession.scala:775)
	at org.apache.spark.sql.execution.SQLExecution$.withNewExecutionId(SQLExecution.scala:64)
	at org.apache.spark.sql.DataFrameWriter.runCommand(DataFrameWriter.scala:989)
	at org.apache.spark.sql.DataFrameWriter.saveToV1Source(DataFrameWriter.scala:438)
	at org.apache.spark.sql.DataFrameWriter.saveInternal(DataFrameWriter.scala:415)
	at org.apache.spark.sql.DataFrameWriter.save(DataFrameWriter.scala:301)
	at org.apache.spark.sql.DataFrameWriter.jdbc(DataFrameWriter.scala:817)
	at sun.reflect.NativeMethodAccessorImpl.invoke0(Native Method)
	at sun.reflect.NativeMethodAccessorImpl.invoke(NativeMethodAccessorImpl.java:62)
	at sun.reflect.DelegatingMethodAccessorImpl.invoke(DelegatingMethodAccessorImpl.java:43)
	at java.lang.reflect.Method.invoke(Method.java:498)
	at py4j.reflection.MethodInvoker.invoke(MethodInvoker.java:244)
	at py4j.reflection.ReflectionEngine.invoke(ReflectionEngine.java:357)
	at py4j.Gateway.invoke(Gateway.java:282)
	at py4j.commands.AbstractCommand.invokeMethod(AbstractCommand.java:132)
	at py4j.commands.CallCommand.execute(CallCommand.java:79)
	at py4j.GatewayConnection.run(GatewayConnection.java:238)
	at java.lang.Thread.run(Thread.java:748)
Caused by: java.sql.BatchUpdateException: Batch entry 0 INSERT INTO Project ("category","count") VALUES ('Workshops',164) was aborted: ERROR: relation "project" does not exist
  Position: 13  Call getNextException to see other errors in the batch.
	at org.postgresql.jdbc.BatchResultHandler.handleError(BatchResultHandler.java:169)
	at org.postgresql.core.ResultHandlerDelegate.handleError(ResultHandlerDelegate.java:52)
	at org.postgresql.core.v3.QueryExecutorImpl.processResults(QueryExecutorImpl.java:2285)
	at org.postgresql.core.v3.QueryExecutorImpl.execute(QueryExecutorImpl.java:520)
	at org.postgresql.jdbc.PgStatement.internalExecuteBatch(PgStatement.java:878)
	at org.postgresql.jdbc.PgStatement.executeBatch(PgStatement.java:901)
	at org.postgresql.jdbc.PgPreparedStatement.executeBatch(PgPreparedStatement.java:1644)
	at org.apache.spark.sql.execution.datasources.jdbc.JdbcUtils$.savePartition(JdbcUtils.scala:692)
	at org.apache.spark.sql.execution.datasources.jdbc.JdbcUtils$.$anonfun$saveTable$1(JdbcUtils.scala:856)
	at org.apache.spark.sql.execution.datasources.jdbc.JdbcUtils$.$anonfun$saveTable$1$adapted(JdbcUtils.scala:854)
	at org.apache.spark.rdd.RDD.$anonfun$foreachPartition$2(RDD.scala:1020)
	at org.apache.spark.rdd.RDD.$anonfun$foreachPartition$2$adapted(RDD.scala:1020)
	at org.apache.spark.SparkContext.$anonfun$runJob$5(SparkContext.scala:2236)
	at org.apache.spark.scheduler.ResultTask.runTask(ResultTask.scala:90)
	at org.apache.spark.scheduler.Task.run(Task.scala:131)
	at org.apache.spark.executor.Executor$TaskRunner.$anonfun$run$3(Executor.scala:497)
	at org.apache.spark.util.Utils$.tryWithSafeFinally(Utils.scala:1439)
	at org.apache.spark.executor.Executor$TaskRunner.run(Executor.scala:500)
	at java.util.concurrent.ThreadPoolExecutor.runWorker(ThreadPoolExecutor.java:1149)
	at java.util.concurrent.ThreadPoolExecutor$Worker.run(ThreadPoolExecutor.java:624)
	... 1 more
Caused by: org.postgresql.util.PSQLException: ERROR: relation "project" does not exist
  Position: 13
	at org.postgresql.core.v3.QueryExecutorImpl.receiveErrorResponse(QueryExecutorImpl.java:2552)
	at org.postgresql.core.v3.QueryExecutorImpl.processResults(QueryExecutorImpl.java:2284)
	... 18 more

[2021-07-02 14:54:20,832] {taskinstance.py:1524} INFO - Marking task as UP_FOR_RETRY. dag_id=Fusemachines_Airflow_project, task_id=most_projects_category, execution_date=20210701T000800, start_date=20210702T090904, end_date=20210702T090920
[2021-07-02 14:54:20,932] {local_task_job.py:151} INFO - Task exited with return code 1
