[2021-07-02 13:29:01,377] {taskinstance.py:876} INFO - Dependencies all met for <TaskInstance: Fusemachines_Airflow_project.sucessful_zero_backers 2021-07-01T00:00:00+00:00 [queued]>
[2021-07-02 13:29:01,384] {taskinstance.py:876} INFO - Dependencies all met for <TaskInstance: Fusemachines_Airflow_project.sucessful_zero_backers 2021-07-01T00:00:00+00:00 [queued]>
[2021-07-02 13:29:01,384] {taskinstance.py:1067} INFO - 
--------------------------------------------------------------------------------
[2021-07-02 13:29:01,384] {taskinstance.py:1068} INFO - Starting attempt 2 of 4
[2021-07-02 13:29:01,384] {taskinstance.py:1069} INFO - 
--------------------------------------------------------------------------------
[2021-07-02 13:29:01,492] {taskinstance.py:1087} INFO - Executing <Task(PythonOperator): sucessful_zero_backers> on 2021-07-01T00:00:00+00:00
[2021-07-02 13:29:01,499] {standard_task_runner.py:52} INFO - Started process 22510 to run task
[2021-07-02 13:29:01,514] {standard_task_runner.py:76} INFO - Running: ['airflow', 'tasks', 'run', 'Fusemachines_Airflow_project', 'sucessful_zero_backers', '2021-07-01T00:00:00+00:00', '--job-id', '29', '--pool', 'default_pool', '--raw', '--subdir', 'DAGS_FOLDER/dag.py', '--cfg-path', '/tmp/tmp88echjeo', '--error-file', '/tmp/tmphyc1vpub']
[2021-07-02 13:29:01,517] {standard_task_runner.py:77} INFO - Job 29: Subtask sucessful_zero_backers
[2021-07-02 13:29:01,691] {logging_mixin.py:104} INFO - Running <TaskInstance: Fusemachines_Airflow_project.sucessful_zero_backers 2021-07-01T00:00:00+00:00 [running]> on host deepika-Inspiron-5570
[2021-07-02 13:29:01,867] {taskinstance.py:1280} INFO - Exporting the following env vars:
AIRFLOW_CTX_DAG_EMAIL=sthadpka93@gmail.com
AIRFLOW_CTX_DAG_OWNER=postgres
AIRFLOW_CTX_DAG_ID=Fusemachines_Airflow_project
AIRFLOW_CTX_TASK_ID=sucessful_zero_backers
AIRFLOW_CTX_EXECUTION_DATE=2021-07-01T00:00:00+00:00
AIRFLOW_CTX_DAG_RUN_ID=scheduled__2021-07-01T00:00:00+00:00
[2021-07-02 13:29:01,973] {taskinstance.py:1481} ERROR - Task failed with exception
Traceback (most recent call last):
  File "/home/deepika/.local/lib/python3.8/site-packages/airflow/models/taskinstance.py", line 1137, in _run_raw_task
    self._prepare_and_execute_task_with_callbacks(context, task)
  File "/home/deepika/.local/lib/python3.8/site-packages/airflow/models/taskinstance.py", line 1311, in _prepare_and_execute_task_with_callbacks
    result = self._execute_task(context, task_copy)
  File "/home/deepika/.local/lib/python3.8/site-packages/airflow/models/taskinstance.py", line 1341, in _execute_task
    result = task_copy.execute(context=context)
  File "/home/deepika/.local/lib/python3.8/site-packages/airflow/operators/python.py", line 150, in execute
    return_value = self.execute_callable()
  File "/home/deepika/.local/lib/python3.8/site-packages/airflow/operators/python.py", line 161, in execute_callable
    return self.python_callable(*self.op_args, **self.op_kwargs)
  File "/home/deepika/airflow/dags/dag.py", line 23, in sucessful_zero_backers
    load_to_db(task1())
  File "/home/deepika/airflow/dags/project.py", line 16, in task1
    return sucessful_zero_backers
NameError: name 'sucessful_zero_backers' is not defined
[2021-07-02 13:29:01,976] {taskinstance.py:1524} INFO - Marking task as UP_FOR_RETRY. dag_id=Fusemachines_Airflow_project, task_id=sucessful_zero_backers, execution_date=20210701T000000, start_date=20210702T074401, end_date=20210702T074401
[2021-07-02 13:29:02,081] {local_task_job.py:151} INFO - Task exited with return code 1
